Workbook

Sheet Monthly Summary
A2: Month | B2: P3 | C2: P4 | D2: P5 | E2: P6 | F2: P7 | G2: P8 | H2: P9 | I2: P10 | J2: P11 | K2: P12 | M2: FY 2026
A4: SD Ramp Plan | B4: =SUMIF('Weekly Summary'!$2:$2,B$2,'Weekly Summary'!6:6) -> 0 | C4: =SUMIF('Weekly Summary'!$2:$2,C$2,'Weekly Summary'!6:6) -> 230400 | D4: =SUMIF('Weekly Summary'!$2:$2,D$2,'Weekly Summary'!6:6) -> 540000 | E4: =SUMIF('Weekly Summary'!$2:$2,E$2,'Weekly Summary'!6:6) -> 1152000 | F4: =SUMIF('Weekly Summary'!$2:$2,F$2,'Weekly Summary'!6:6) -> 1592524.8 | G4: =SUMIF('Weekly Summary'!$2:$2,G$2,'Weekly Summary'!6:6) -> 1728000 | H4: =SUMIF('Weekly Summary'!$2:$2,H$2,'Weekly Summary'!6:6) -> 1871424 | I4: =SUMIF('Weekly Summary'!$2:$2,I$2,'Weekly Summary'!6:6) -> 2592000 | ... K4: =SUMIF('Weekly Summary'!$2:$2,K$2,'Weekly Summary'!6:6) -> 1772928 | M4: =SUM(C4:L4) -> 13252205
A5: New SD Plant Plan | B5: =SUMIF('Weekly Summary'!$2:$2,B$2,'Weekly Summary'!7:7) -> 0 | C5: =SUMIF('Weekly Summary'!$2:$2,C$2,'Weekly Summary'!7:7) -> 0 | D5: =SUMIF('Weekly Summary'!$2:$2,D$2,'Weekly Summary'!7:7) -> 0 | E5: =SUMIF('Weekly Summary'!$2:$2,E$2,'Weekly Summary'!7:7) -> 0 | F5: =SUMIF('Weekly Summary'!$2:$2,F$2,'Weekly Summary'!7:7) -> 0 | G5: =SUMIF('Weekly Summary'!$2:$2,G$2,'Weekly Summary'!7:7) -> 1120000 | H5: =SUMIF('Weekly Summary'!$2:$2,H$2,'Weekly Summary'!7:7) -> 1920000 | I5: =SUMIF('Weekly Summary'!$2:$2,I$2,'Weekly Summary'!7:7) -> 3000000 | ... K5: =SUMIF('Weekly Summary'!$2:$2,K$2,'Weekly Summary'!7:7) -> 2880000 | M5: =SUM(C5:L5) -> 11800000
A7: SD Produced | B7: =SUMIF('Weekly Summary'!$2:$2,B$2,'Weekly Summary'!9:9) -> 76320 | C7: =SUMIF('Weekly Summary'!$2:$2,C$2,'Weekly Summary'!9:9) -> 1122876.2 | D7: =SUMIF('Weekly Summary'!$2:$2,D$2,'Weekly Summary'!9:9) -> 908334.12 | E7: =SUMIF('Weekly Summary'!$2:$2,E$2,'Weekly Summary'!9:9) -> 1025020.6 | F7: =SUMIF('Weekly Summary'!$2:$2,F$2,'Weekly Summary'!9:9) -> 1092496.1 | G7: =SUMIF('Weekly Summary'!$2:$2,G$2,'Weekly Summary'!9:9) -> 1073207.1 | H7: =SUMIF('Weekly Summary'!$2:$2,H$2,'Weekly Summary'!9:9) -> 460981.17 | I7: =SUMIF('Weekly Summary'!$2:$2,I$2,'Weekly Summary'!9:9) -> 0 | ... K7: =SUMIF('Weekly Summary'!$2:$2,K$2,'Weekly Summary'!9:9) -> 0 | M7: =SUM(C7:L7) -> 5682915.2
A8: SD Packed | B8: =SUMIF('Weekly Summary'!$2:$2,B$2,'Weekly Summary'!10:10) -> 76320 | C8: =SUMIF('Weekly Summary'!$2:$2,C$2,'Weekly Summary'!10:10) -> 996390 | D8: =SUMIF('Weekly Summary'!$2:$2,D$2,'Weekly Summary'!10:10) -> 801000 | E8: =SUMIF('Weekly Summary'!$2:$2,E$2,'Weekly Summary'!10:10) -> 1090392 | F8: =SUMIF('Weekly Summary'!$2:$2,F$2,'Weekly Summary'!10:10) -> 909570 | G8: =SUMIF('Weekly Summary'!$2:$2,G$2,'Weekly Summary'!10:10) -> 867120 | H8: =SUMIF('Weekly Summary'!$2:$2,H$2,'Weekly Summary'!10:10) -> 457460 | I8: =SUMIF('Weekly Summary'!$2:$2,I$2,'Weekly Summary'!10:10) -> 0 | ... K8: =SUMIF('Weekly Summary'!$2:$2,K$2,'Weekly Summary'!10:10) -> 0 | M8: =SUM(C8:L8) -> 5121932
A11: Produced v Ramp Plan | B11: =+B7-B4 -> 76320 | C11: =+C7-C4 -> 892476.17 | D11: =+D7-D4 -> 368334.12 | E11: =+E7-E4 -> -126979.41 | F11: =+F7-F4 -> -500028.75 | G11: =+G7-G4 -> -654792.89 | H11: =+H7-H4 -> -1410442.8 | M11: =SUM(B11:L11) -> -1355113.6
A12: Packed v Ramp Plan | B12: =+B8-B4 -> 76320 | C12: =+C8-C4 -> 765990 | D12: =+D8-D4 -> 261000 | E12: =+E8-E4 -> -61608 | F12: =+F8-F4 -> -682954.8 | G12: =+G8-G4 -> -860880 | H12: =+H8-H4 -> -1413964 | M12: =SUM(B12:L12) -> -1916096.8
A13: Produced v New Plant Plan | G13: =+G7-G5 -> -46792.889 | H13: =+H7-H5 -> -1459018.8 | M13: =SUM(B13:L13) -> -1505811.7
A14: Packed v New Plant Plan | G14: =+G8-G5 -> -252880 | H14: =+H8-H5 -> -1462540 | M14: =SUM(B14:L14) -> -1715420
A16: Waste Pcs Production | B16: =SUMIF('Weekly Summary'!$2:$2,B$2,'Weekly Summary'!18:18) -> 0 | C16: =SUMIF('Weekly Summary'!$2:$2,C$2,'Weekly Summary'!18:18) -> 59346.173 | D16: =SUMIF('Weekly Summary'!$2:$2,D$2,'Weekly Summary'!18:18) -> 54550.123 | E16: =SUMIF('Weekly Summary'!$2:$2,E$2,'Weekly Summary'!18:18) -> 40912.593 | F16: =SUMIF('Weekly Summary'!$2:$2,F$2,'Weekly Summary'!18:18) -> 87938.054 | G16: =SUMIF('Weekly Summary'!$2:$2,G$2,'Weekly Summary'!18:18) -> 90311.111 | H16: =SUMIF('Weekly Summary'!$2:$2,H$2,'Weekly Summary'!18:18) -> 37910.123 | I16: =SUMIF('Weekly Summary'!$2:$2,I$2,'Weekly Summary'!18:18) -> 0 | ... K16: =SUMIF('Weekly Summary'!$2:$2,K$2,'Weekly Summary'!18:18) -> 0 | M16: =SUM(C16:K16) -> 370968.18 | N16: =+M16/SUM(M16:M17) -> 0.90260813
A17: Waste Pcs Packing | B17: =SUMIF('Weekly Summary'!$2:$2,B$2,'Weekly Summary'!19:19) -> 0 | C17: =SUMIF('Weekly Summary'!$2:$2,C$2,'Weekly Summary'!19:19) -> 0 | D17: =SUMIF('Weekly Summary'!$2:$2,D$2,'Weekly Summary'!19:19) -> 3950.6173 | E17: =SUMIF('Weekly Summary'!$2:$2,E$2,'Weekly Summary'!19:19) -> 4456.2963 | F17: =SUMIF('Weekly Summary'!$2:$2,F$2,'Weekly Summary'!19:19) -> 13921.975 | G17: =SUMIF('Weekly Summary'!$2:$2,G$2,'Weekly Summary'!19:19) -> 11093.333 | H17: =SUMIF('Weekly Summary'!$2:$2,H$2,'Weekly Summary'!19:19) -> 6605.4321 | I17: =SUMIF('Weekly Summary'!$2:$2,I$2,'Weekly Summary'!19:19) -> 0 | ... K17: =SUMIF('Weekly Summary'!$2:$2,K$2,'Weekly Summary'!19:19) -> 0 | M17: =SUM(C17:K17) -> 40027.654 | N17: =+M17/SUM(M16:M17) -> 0.097391874
A18: Waste % (v Produced) | B18: =IFERROR(SUM(B16:B17)/B7,"") -> 0 | C18: =IFERROR(SUM(C16:C17)/C7,"") -> 0.05285193 | D18: =IFERROR(SUM(D16:D17)/D7,"") -> 0.064404429 | E18: =IFERROR(SUM(E16:E17)/E7,"") -> 0.044261441 | F18: =IFERROR(SUM(F16:F17)/F7,"") -> 0.093236062 | G18: =IFERROR(SUM(G16:G17)/G7,"") -> 0.094487302 | H18: =IFERROR(SUM(H16:H17)/H7,"") -> 0.096566971 | I18: =IFERROR(SUM(I16:I17)/I7,"") | ... K18: =IFERROR(SUM(K16:K17)/K7,"") | L18: =+IFERROR(L16/L8,"") | M18: =IFERROR(SUM(M16:M17)/M7,"") -> 0.072321303
A20: Bao Ramp Plan | B20: =SUMIF('Weekly Summary'!$2:$2,B$2,'Weekly Summary'!22:22) -> 0 | C20: =SUMIF('Weekly Summary'!$2:$2,C$2,'Weekly Summary'!22:22) -> 311107.5 | D20: =SUMIF('Weekly Summary'!$2:$2,D$2,'Weekly Summary'!22:22) -> 493762.5 | E20: =SUMIF('Weekly Summary'!$2:$2,E$2,'Weekly Summary'!22:22) -> 1287000 | F20: =SUMIF('Weekly Summary'!$2:$2,F$2,'Weekly Summary'!22:22) -> 2200770 | G20: =SUMIF('Weekly Summary'!$2:$2,G$2,'Weekly Summary'!22:22) -> 2316600 | H20: =SUMIF('Weekly Summary'!$2:$2,H$2,'Weekly Summary'!22:22) -> 542953.12 | I20: =SUMIF('Weekly Summary'!$2:$2,I$2,'Weekly Summary'!22:22) -> 0 | ... K20: =SUMIF('Weekly Summary'!$2:$2,K$2,'Weekly Summary'!22:22) -> 0 | M20: =SUM(B20:L20) -> 7152193.1
A21: New Bao Plant Plan | B21: =SUMIF('Weekly Summary'!$2:$2,B$2,'Weekly Summary'!23:23) -> 0 | C21: =SUMIF('Weekly Summary'!$2:$2,C$2,'Weekly Summary'!23:23) -> 0 | D21: =SUMIF('Weekly Summary'!$2:$2,D$2,'Weekly Summary'!23:23) -> 0 | E21: =SUMIF('Weekly Summary'!$2:$2,E$2,'Weekly Summary'!23:23) -> 0 | F21: =SUMIF('Weekly Summary'!$2:$2,F$2,'Weekly Summary'!23:23) -> 0 | G21: =SUMIF('Weekly Summary'!$2:$2,G$2,'Weekly Summary'!23:23) -> 210000 | H21: =SUMIF('Weekly Summary'!$2:$2,H$2,'Weekly Summary'!23:23) -> 1350000 | I21: =SUMIF('Weekly Summary'!$2:$2,I$2,'Weekly Summary'!23:23) -> 1875000 | ... K21: =SUMIF('Weekly Summary'!$2:$2,K$2,'Weekly Summary'!23:23) -> 1350000 | M21: =SUM(C21:L21) -> 6135000
A23: Bao Produced | B23: =SUMIF('Weekly Summary'!$2:$2,B$2,'Weekly Summary'!25:25) -> 0 | C23: =SUMIF('Weekly Summary'!$2:$2,C$2,'Weekly Summary'!25:25) -> 0 | D23: =SUMIF('Weekly Summary'!$2:$2,D$2,'Weekly Summary'!25:25) -> 92130.4 | E23: =SUMIF('Weekly Summary'!$2:$2,E$2,'Weekly Summary'!25:25) -> 95424 | F23: =SUMIF('Weekly Summary'!$2:$2,F$2,'Weekly Summary'!25:25) -> 317158.5 | G23: =SUMIF('Weekly Summary'!$2:$2,G$2,'Weekly Summary'!25:25) -> 507382.3 | H23: =SUMIF('Weekly Summary'!$2:$2,H$2,'Weekly Summary'!25:25) -> 95164.6 | I23: =SUMIF('Weekly Summary'!$2:$2,I$2,'Weekly Summary'!25:25) -> 0 | ... K23: =SUMIF('Weekly Summary'!$2:$2,K$2,'Weekly Summary'!25:25) -> 0 | M23: =SUM(C23:L23) -> 1107259.8
A24: Bao Packed | B24: =SUMIF('Weekly Summary'!$2:$2,B$2,'Weekly Summary'!26:26) -> 0 | C24: =SUMIF('Weekly Summary'!$2:$2,C$2,'Weekly Summary'!26:26) -> 0 | D24: =SUMIF('Weekly Summary'!$2:$2,D$2,'Weekly Summary'!26:26) -> 35152 | E24: =SUMIF('Weekly Summary'!$2:$2,E$2,'Weekly Summary'!26:26) -> 86600 | F24: =SUMIF('Weekly Summary'!$2:$2,F$2,'Weekly Summary'!26:26) -> 267869 | G24: =SUMIF('Weekly Summary'!$2:$2,G$2,'Weekly Summary'!26:26) -> 393402 | H24: =SUMIF('Weekly Summary'!$2:$2,H$2,'Weekly Summary'!26:26) -> 42104 | I24: =SUMIF('Weekly Summary'!$2:$2,I$2,'Weekly Summary'!26:26) -> 0 | ... K24: =SUMIF('Weekly Summary'!$2:$2,K$2,'Weekly Summary'!26:26) -> 0 | M24: =SUM(C24:L24) -> 825127
A27: Produced v Ramp Plan | B27: =+B23-B20 -> 0 | C27: =+C23-C20 -> -311107.5 | D27: =+D23-D20 -> -401632.1 | E27: =+E23-E20 -> -1191576 | F27: =+F23-F20 -> -1883611.5 | G27: =+G23-G20 -> -1809217.7 | H27: =+H23-H20 -> -447788.53 | M27: =SUM(B27:L27) -> -6044933.3
A28: Packed v Ramp Plan | B28: =+B24-B20 -> 0 | C28: =+C24-C20 -> -311107.5 | D28: =+D24-D20 -> -458610.5 | E28: =+E24-E20 -> -1200400 | F28: =+F24-F20 -> -1932901 | G28: =+G24-G20 -> -1923198 | H28: =+H24-H20 -> -500849.12 | M28: =SUM(B28:L28) -> -6327066.1
A29: Produced v New Plant Plan | B29: =+B23-B21 -> 0 | C29: =+C23-C21 -> 0 | D29: =+D23-D21 -> 92130.4 | E29: =+E23-E21 -> 95424 | F29: =+F23-F21 -> 317158.5 | G29: =+G23-G21 -> 297382.3 | H29: =+H23-H21 -> -1254835.4 | M29: =SUM(B29:L29) -> -452740.2
A30: Packed v New Plant Plan | B30: =+B24-B21 -> 0 | C30: =+C24-C21 -> 0 | D30: =+D24-D21 -> 35152 | E30: =+E24-E21 -> 86600 | F30: =+F24-F21 -> 267869 | G30: =+G24-G21 -> 183402 | H30: =+H24-H21 -> -1307896 | M30: =SUM(B30:L30) -> -734873
A32: Waste Pcs Production | B32: =SUMIF('Weekly Summary'!$2:$2,B$2,'Weekly Summary'!34:34) -> 0 | C32: =SUMIF('Weekly Summary'!$2:$2,C$2,'Weekly Summary'!34:34) -> 0 | D32: =SUMIF('Weekly Summary'!$2:$2,D$2,'Weekly Summary'!34:34) -> 9318.4 | E32: =SUMIF('Weekly Summary'!$2:$2,E$2,'Weekly Summary'!34:34) -> 12736 | F32: =SUMIF('Weekly Summary'!$2:$2,F$2,'Weekly Summary'!34:34) -> 27520 | G32: =SUMIF('Weekly Summary'!$2:$2,G$2,'Weekly Summary'!34:34) -> 34444.8 | H32: =SUMIF('Weekly Summary'!$2:$2,H$2,'Weekly Summary'!34:34) -> 15609.6 | I32: =SUMIF('Weekly Summary'!$2:$2,I$2,'Weekly Summary'!34:34) -> 0 | ... K32: =SUMIF('Weekly Summary'!$2:$2,K$2,'Weekly Summary'!34:34) -> 0 | M32: =SUM(C32:K32) -> 99628.8 | N32: =+M32/SUM(M32:M33) -> 0.83084929
A33: Waste Pcs Packing | B33: =SUMIF('Weekly Summary'!$2:$2,B$2,'Weekly Summary'!35:35) -> 0 | C33: =SUMIF('Weekly Summary'!$2:$2,C$2,'Weekly Summary'!35:35) -> 0 | D33: =SUMIF('Weekly Summary'!$2:$2,D$2,'Weekly Summary'!35:35) -> 0 | E33: =SUMIF('Weekly Summary'!$2:$2,E$2,'Weekly Summary'!35:35) -> 332.8 | F33: =SUMIF('Weekly Summary'!$2:$2,F$2,'Weekly Summary'!35:35) -> 8705.6 | G33: =SUMIF('Weekly Summary'!$2:$2,G$2,'Weekly Summary'!35:35) -> 9881.6 | H33: =SUMIF('Weekly Summary'!$2:$2,H$2,'Weekly Summary'!35:35) -> 1363.2 | I33: =SUMIF('Weekly Summary'!$2:$2,I$2,'Weekly Summary'!35:35) -> 0 | ... K33: =SUMIF('Weekly Summary'!$2:$2,K$2,'Weekly Summary'!35:35) -> 0 | M33: =SUM(C33:K33) -> 20283.2 | N33: =+M33/SUM(M32:M33) -> 0.16915071
A34: Waste % (v Produced) | B34: =IFERROR(SUM(B32:B33)/B23,"") | C34: =IFERROR(SUM(C32:C33)/C23,"") | D34: =IFERROR(SUM(D32:D33)/D23,"") -> 0.1011436 | E34: =IFERROR(SUM(E32:E33)/E23,"") -> 0.13695506 | F34: =IFERROR(SUM(F32:F33)/F23,"") -> 0.11421923 | G34: =IFERROR(SUM(G32:G33)/G23,"") -> 0.087362921 | H34: =IFERROR(SUM(H32:H33)/H23,"") -> 0.17835203 | I34: =IFERROR(SUM(I32:I33)/I23,"") | ... K34: =IFERROR(SUM(K32:K33)/K23,"") | L34: =+IFERROR(L32/L24,"") | M34: =IFERROR(SUM(M32:M33)/M23,"") -> 0.10829617
A36: Total Pieces Packed | C36: =+C8+C24 -> 996390 | D36: =+D8+D24 -> 836152 | E36: =+E8+E24 -> 1176992 | F36: =+F8+F24 -> 1177439 | G36: =+G8+G24 -> 1260522 | H36: =+H8+H24 -> 499564 | I36: =+I8+I24 -> 0 | J36: =+J8+J24 -> 0 | K36: =+K8+K24 -> 0

Sheet Weekly Summary
A2: Month | B2: P3 | C2: P4 | D2: P4 | E2: P4 | F2: P4 | G2: P4 | H2: P5 | I2: P5 | J2: P5 | K2: P5 | L2: P6 | M2: P6 | N2: P6 | O2: P6 | P2: P7 | Q2: P7 | R2: P7 | S2: P7 | T2: P7 | U2: P8 | V2: P8 | W2: P8 | X2: P8 | Y2: P9 | Z2: P9 | AA2: P9 | AB2: P9 | AC2: P10 | AD2: P10 | AE2: P10 | AF2: P10 | AG2: P10 | AH2: P11 | AI2: P11 | AJ2: P11 | AK2: P11 | AL2: P12 | AM2: P12 | AN2: P12 | AO2: P12 | AP2: P12
A3: Week | B3: 46104 | C3: 46111 | D3: =+C3+7 -> 46118 | E3: =+D3+7 -> 46125 | F3: =+E3+7 -> 46132 | G3: =+F3+7 -> 46139 | H3: =+G3+7 -> 46146 | I3: =+H3+7 -> 46153 | J3: =+I3+7 -> 46160 | K3: =+J3+7 -> 46167 | ... AP3: =+AO3+7 -> 46384 | AR3: FY 2026
A4: Week # | B4: =+WEEKNUM(B3) -> 13 | C4: =+WEEKNUM(C3) -> 14 | D4: =+WEEKNUM(D3) -> 15 | E4: =+WEEKNUM(E3) -> 16 | F4: =+WEEKNUM(F3) -> 17 | G4: =+WEEKNUM(G3) -> 18 | H4: =+WEEKNUM(H3) -> 19 | I4: =+WEEKNUM(I3) -> 20 | ... AP4: =+WEEKNUM(AP3) -> 53
A6: SD Ramp Plan | B6: =SUMIF('Daily Summary New'!$3:$3,B$4,'Daily Summary New'!6:6) -> 0 | C6: =SUMIF('Daily Summary New'!$3:$3,C$4,'Daily Summary New'!6:6) -> 46080 | D6: =SUMIF('Daily Summary New'!$3:$3,D$4,'Daily Summary New'!6:6) -> 46080 | E6: =SUMIF('Daily Summary New'!$3:$3,E$4,'Daily Summary New'!6:6) -> 46080 | F6: =SUMIF('Daily Summary New'!$3:$3,F$4,'Daily Summary New'!6:6) -> 46080 | G6: =SUMIF('Daily Summary New'!$3:$3,G$4,'Daily Summary New'!6:6) -> 46080 | H6: =SUMIF('Daily Summary New'!$3:$3,H$4,'Daily Summary New'!6:6) -> 144000 | I6: =SUMIF('Daily Summary New'!$3:$3,I$4,'Daily Summary New'!6:6) -> 144000 | ... AP6: =SUMIF('Daily Summary New'!$3:$3,AP$4,'Daily Summary New'!6:6) -> 0 | AR6: =SUM(C6:AQ6) -> 13252205
A7: New SD Plant Plan | B7: =SUMIF('Daily Summary New'!$3:$3,B$4,'Daily Summary New'!7:7) -> 0 | C7: =SUMIF('Daily Summary New'!$3:$3,C$4,'Daily Summary New'!7:7) -> 0 | D7: =SUMIF('Daily Summary New'!$3:$3,D$4,'Daily Summary New'!7:7) -> 0 | E7: =SUMIF('Daily Summary New'!$3:$3,E$4,'Daily Summary New'!7:7) -> 0 | F7: =SUMIF('Daily Summary New'!$3:$3,F$4,'Daily Summary New'!7:7) -> 0 | G7: =SUMIF('Daily Summary New'!$3:$3,G$4,'Daily Summary New'!7:7) -> 0 | H7: =SUMIF('Daily Summary New'!$3:$3,H$4,'Daily Summary New'!7:7) -> 0 | I7: =SUMIF('Daily Summary New'!$3:$3,I$4,'Daily Summary New'!7:7) -> 0 | ... AP7: =SUMIF('Daily Summary New'!$3:$3,AP$4,'Daily Summary New'!7:7) -> 0 | AR7: =SUM(C7:AQ7) -> 11800000
A9: SD Produced | B9: =SUMIF('Daily Summary New'!$3:$3,B$4,'Daily Summary New'!9:9) -> 76320 | C9: =SUMIF('Daily Summary New'!$3:$3,C$4,'Daily Summary New'!9:9) -> 155040 | D9: =SUMIF('Daily Summary New'!$3:$3,D$4,'Daily Summary New'!9:9) -> 171840 | E9: =SUMIF('Daily Summary New'!$3:$3,E$4,'Daily Summary New'!9:9) -> 216919.01 | F9: =SUMIF('Daily Summary New'!$3:$3,F$4,'Daily Summary New'!9:9) -> 259877.04 | G9: =SUMIF('Daily Summary New'!$3:$3,G$4,'Daily Summary New'!9:9) -> 319200.12 | H9: =SUMIF('Daily Summary New'!$3:$3,H$4,'Daily Summary New'!9:9) -> 251410.37 | I9: =SUMIF('Daily Summary New'!$3:$3,I$4,'Daily Summary New'!9:9) -> 266266.17 | ... AP9: =SUMIF('Daily Summary New'!$3:$3,AP$4,'Daily Summary New'!9:9) -> 0 | AR9: =SUM(C9:AQ9) -> 5682915.2
A10: SD Packed | B10: =SUMIF('Daily Summary New'!$3:$3,B$4,'Daily Summary New'!10:10) -> 76320 | C10: =SUMIF('Daily Summary New'!$3:$3,C$4,'Daily Summary New'!10:10) -> 155040 | D10: =SUMIF('Daily Summary New'!$3:$3,D$4,'Daily Summary New'!10:10) -> 171840 | E10: =SUMIF('Daily Summary New'!$3:$3,E$4,'Daily Summary New'!10:10) -> 189960 | F10: =SUMIF('Daily Summary New'!$3:$3,F$4,'Daily Summary New'!10:10) -> 246840 | G10: =SUMIF('Daily Summary New'!$3:$3,G$4,'Daily Summary New'!10:10) -> 232710 | H10: =SUMIF('Daily Summary New'!$3:$3,H$4,'Daily Summary New'!10:10) -> 235500 | I10: =SUMIF('Daily Summary New'!$3:$3,I$4,'Daily Summary New'!10:10) -> 229320 | ... AP10: =SUMIF('Daily Summary New'!$3:$3,AP$4,'Daily Summary New'!10:10) -> 0 | AR10: =SUM(C10:AQ10) -> 5121932
A13: Produced v Ramp Plan | B13: =+B9-B6 -> 76320 | C13: =+C9-C6 -> 108960 | D13: =+D9-D6 -> 125760 | E13: =+E9-E6 -> 170839.01 | F13: =+F9-F6 -> 213797.04 | G13: =+G9-G6 -> 273120.12 | H13: =+H9-H6 -> 107410.37 | I13: =+I9-I6 -> 122266.17 | ... Z13: =+Z9-Z6 -> -393984 | AR13: =SUM(C13:AQ13) -> -446473.57
A14: Packed v Ramp Plan | B14: =+B10-B6 -> 76320 | C14: =+C10-C6 -> 108960 | D14: =+D10-D6 -> 125760 | E14: =+E10-E6 -> 143880 | F14: =+F10-F6 -> 200760 | G14: =+G10-G6 -> 186630 | H14: =+H10-H6 -> 91500 | I14: =+I10-I6 -> 85320 | ... Z14: =+Z10-Z6 -> -300624 | AR14: =SUM(C14:AQ14) -> -1007456.8
A15: Produced v New Plant Plan | U15: =+U9-U7 -> 4129.7778 | V15: =+V9-V7 -> -63036.84 | W15: =+W9-W7 -> -43112.296 | X15: =+X9-X7 -> 55226.469 | Y15: =+Y9-Y7 -> 100981.17 | Z15: =+Z9-Z7 -> -360000 | AR15: =SUM(C15:AQ15) -> -305811.72
A16: Packed v New Plant Plan | U16: =+U10-U7 -> -84800 | V16: =+V10-V7 -> -122360 | W16: =+W10-W7 -> -15340 | X16: =+X10-X7 -> -30380 | Y16: =+Y10-Y7 -> 4100 | Z16: =+Z10-Z7 -> -266640 | AR16: =SUM(C16:AQ16) -> -515420
A18: Waste Pcs Production | B18: =SUMIF('Daily Summary New'!$3:$3,B$4,'Daily Summary New'!18:18) -> 0 | C18: =SUMIF('Daily Summary New'!$3:$3,C$4,'Daily Summary New'!18:18) -> 0 | D18: =SUMIF('Daily Summary New'!$3:$3,D$4,'Daily Summary New'!18:18) -> 0 | E18: =SUMIF('Daily Summary New'!$3:$3,E$4,'Daily Summary New'!18:18) -> 26959.012 | F18: =SUMIF('Daily Summary New'!$3:$3,F$4,'Daily Summary New'!18:18) -> 13037.037 | G18: =SUMIF('Daily Summary New'!$3:$3,G$4,'Daily Summary New'!18:18) -> 19350.123 | H18: =SUMIF('Daily Summary New'!$3:$3,H$4,'Daily Summary New'!18:18) -> 25410.37 | I18: =SUMIF('Daily Summary New'!$3:$3,I$4,'Daily Summary New'!18:18) -> 19026.173 | ... AP18: =SUMIF('Daily Summary New'!$3:$3,AP$4,'Daily Summary New'!18:18) -> 0 | AR18: =SUM(C18:AP18) -> 370968.18 | AS18: =+AR18/SUM(AR18:AR19) -> 0.90260813
A19: Waste Pcs Packing | B19: =SUMIF('Daily Summary New'!$3:$3,B$4,'Daily Summary New'!19:19) -> 0 | C19: =SUMIF('Daily Summary New'!$3:$3,C$4,'Daily Summary New'!19:19) -> 0 | D19: =SUMIF('Daily Summary New'!$3:$3,D$4,'Daily Summary New'!19:19) -> 0 | E19: =SUMIF('Daily Summary New'!$3:$3,E$4,'Daily Summary New'!19:19) -> 0 | F19: =SUMIF('Daily Summary New'!$3:$3,F$4,'Daily Summary New'!19:19) -> 0 | G19: =SUMIF('Daily Summary New'!$3:$3,G$4,'Daily Summary New'!19:19) -> 0 | H19: =SUMIF('Daily Summary New'!$3:$3,H$4,'Daily Summary New'!19:19) -> 0 | I19: =SUMIF('Daily Summary New'!$3:$3,I$4,'Daily Summary New'!19:19) -> 0 | ... AP19: =SUMIF('Daily Summary New'!$3:$3,AP$4,'Daily Summary New'!19:19) -> 0 | AR19: =SUM(C19:AP19) -> 40027.654 | AS19: =+AR19/SUM(AR18:AR19) -> 0.097391874
A20: Waste % (v Produced) | B20: =IFERROR(SUM(B18:B19)/B9,"") -> 0 | C20: =IFERROR(SUM(C18:C19)/C9,"") -> 0 | D20: =IFERROR(SUM(D18:D19)/D9,"") -> 0 | E20: =IFERROR(SUM(E18:E19)/E9,"") -> 0.12428146 | F20: =IFERROR(SUM(F18:F19)/F9,"") -> 0.050166175 | G20: =IFERROR(SUM(G18:G19)/G9,"") -> 0.060620664 | H20: =IFERROR(SUM(H18:H19)/H9,"") -> 0.10107129 | I20: =IFERROR(SUM(I18:I19)/I9,"") -> 0.071455464 | ... AP20: =IFERROR(SUM(AP18:AP19)/AP9,"") | AR20: =IFERROR(SUM(AR18:AR19)/AR9,"") -> 0.072321303
A22: Bao Ramp Plan | B22: =SUMIF('Daily Summary New'!$3:$3,B$4,'Daily Summary New'!22:22) -> 0 | C22: =SUMIF('Daily Summary New'!$3:$3,C$4,'Daily Summary New'!22:22) -> 59400 | D22: =SUMIF('Daily Summary New'!$3:$3,D$4,'Daily Summary New'!22:22) -> 59400 | E22: =SUMIF('Daily Summary New'!$3:$3,E$4,'Daily Summary New'!22:22) -> 59400 | F22: =SUMIF('Daily Summary New'!$3:$3,F$4,'Daily Summary New'!22:22) -> 59400 | G22: =SUMIF('Daily Summary New'!$3:$3,G$4,'Daily Summary New'!22:22) -> 73507.5 | H22: =SUMIF('Daily Summary New'!$3:$3,H$4,'Daily Summary New'!22:22) -> 129937.5 | I22: =SUMIF('Daily Summary New'!$3:$3,I$4,'Daily Summary New'!22:22) -> 129937.5 | ... AP22: =SUMIF('Daily Summary New'!$3:$3,AP$4,'Daily Summary New'!22:22) -> 0 | AR22: =SUM(C22:AQ22) -> 7152193.1
A23: New Bao Plant Plan | B23: =SUMIF('Daily Summary New'!$3:$3,B$4,'Daily Summary New'!23:23) -> 0 | C23: =SUMIF('Daily Summary New'!$3:$3,C$4,'Daily Summary New'!23:23) -> 0 | D23: =SUMIF('Daily Summary New'!$3:$3,D$4,'Daily Summary New'!23:23) -> 0 | E23: =SUMIF('Daily Summary New'!$3:$3,E$4,'Daily Summary New'!23:23) -> 0 | F23: =SUMIF('Daily Summary New'!$3:$3,F$4,'Daily Summary New'!23:23) -> 0 | G23: =SUMIF('Daily Summary New'!$3:$3,G$4,'Daily Summary New'!23:23) -> 0 | H23: =SUMIF('Daily Summary New'!$3:$3,H$4,'Daily Summary New'!23:23) -> 0 | I23: =SUMIF('Daily Summary New'!$3:$3,I$4,'Daily Summary New'!23:23) -> 0 | ... AP23: =SUMIF('Daily Summary New'!$3:$3,AP$4,'Daily Summary New'!23:23) -> 0 | AR23: =SUM(C23:AQ23) -> 6135000
A25: Bao Produced | B25: =SUMIF('Daily Summary New'!$3:$3,B$4,'Daily Summary New'!25:25) -> 0 | C25: =SUMIF('Daily Summary New'!$3:$3,C$4,'Daily Summary New'!25:25) -> 0 | D25: =SUMIF('Daily Summary New'!$3:$3,D$4,'Daily Summary New'!25:25) -> 0 | E25: =SUMIF('Daily Summary New'!$3:$3,E$4,'Daily Summary New'!25:25) -> 0 | F25: =SUMIF('Daily Summary New'!$3:$3,F$4,'Daily Summary New'!25:25) -> 0 | G25: =SUMIF('Daily Summary New'!$3:$3,G$4,'Daily Summary New'!25:25) -> 0 | H25: =SUMIF('Daily Summary New'!$3:$3,H$4,'Daily Summary New'!25:25) -> 192 | I25: =SUMIF('Daily Summary New'!$3:$3,I$4,'Daily Summary New'!25:25) -> 18192.4 | ... AP25: =SUMIF('Daily Summary New'!$3:$3,AP$4,'Daily Summary New'!25:25) -> 0 | AR25: =SUM(C25:AQ25) -> 1107259.8
A26: Bao Packed | B26: =SUMIF('Daily Summary New'!$3:$3,B$4,'Daily Summary New'!26:26) -> 0 | C26: =SUMIF('Daily Summary New'!$3:$3,C$4,'Daily Summary New'!26:26) -> 0 | D26: =SUMIF('Daily Summary New'!$3:$3,D$4,'Daily Summary New'!26:26) -> 0 | E26: =SUMIF('Daily Summary New'!$3:$3,E$4,'Daily Summary New'!26:26) -> 0 | F26: =SUMIF('Daily Summary New'!$3:$3,F$4,'Daily Summary New'!26:26) -> 0 | G26: =SUMIF('Daily Summary New'!$3:$3,G$4,'Daily Summary New'!26:26) -> 0 | H26: =SUMIF('Daily Summary New'!$3:$3,H$4,'Daily Summary New'!26:26) -> 0 | I26: =SUMIF('Daily Summary New'!$3:$3,I$4,'Daily Summary New'!26:26) -> 0 | ... AP26: =SUMIF('Daily Summary New'!$3:$3,AP$4,'Daily Summary New'!26:26) -> 0 | AR26: =SUM(C26:AQ26) -> 825127
A29: Produced v Ramp Plan | B29: =+B25-B22 -> 0 | C29: =+C25-C22 -> -59400 | D29: =+D25-D22 -> -59400 | E29: =+E25-E22 -> -59400 | F29: =+F25-F22 -> -59400 | G29: =+G25-G22 -> -73507.5 | H29: =+H25-H22 -> -129745.5 | I29: =+I25-I22 -> -111745.1 | ... Z29: =+Z25-Z22 -> 0 | AR29: =SUM(C29:AQ29) -> -6044933.3
A30: Packed v Ramp Plan | B30: =+B26-B22 -> 0 | C30: =+C26-C22 -> -59400 | D30: =+D26-D22 -> -59400 | E30: =+E26-E22 -> -59400 | F30: =+F26-F22 -> -59400 | G30: =+G26-G22 -> -73507.5 | H30: =+H26-H22 -> -129937.5 | I30: =+I26-I22 -> -129937.5 | ... Z30: =+Z26-Z22 -> 0 | AR30: =SUM(C30:AQ30) -> -6327066.1
A31: Produced v New Plant Plan | U31: =+U25-U23 -> 163389.6 | V31: =+V25-V23 -> 139180.8 | W31: =+W25-W23 -> 53970.4 | X31: =+X25-X23 -> -59158.5 | Y31: =+Y25-Y23 -> -204835.4 | Z31: =+Z25-Z23 -> -300000 | AR31: =SUM(C31:AQ31) -> -207453.1
A32: Packed v New Plant Plan | U32: =+U26-U23 -> 99360 | V32: =+V26-V23 -> 118018 | W32: =+W26-W23 -> 53056 | X32: =+X26-X23 -> -87032 | Y32: =+Y26-Y23 -> -257896 | Z32: =+Z26-Z23 -> -300000 | AR32: =SUM(C32:AQ32) -> -374494
A34: Waste Pcs Production | B34: =SUMIF('Daily Summary New'!$3:$3,B$4,'Daily Summary New'!34:34) -> 0 | C34: =SUMIF('Daily Summary New'!$3:$3,C$4,'Daily Summary New'!34:34) -> 0 | D34: =SUMIF('Daily Summary New'!$3:$3,D$4,'Daily Summary New'!34:34) -> 0 | E34: =SUMIF('Daily Summary New'!$3:$3,E$4,'Daily Summary New'!34:34) -> 0 | F34: =SUMIF('Daily Summary New'!$3:$3,F$4,'Daily Summary New'!34:34) -> 0 | G34: =SUMIF('Daily Summary New'!$3:$3,G$4,'Daily Summary New'!34:34) -> 0 | H34: =SUMIF('Daily Summary New'!$3:$3,H$4,'Daily Summary New'!34:34) -> 192 | I34: =SUMIF('Daily Summary New'!$3:$3,I$4,'Daily Summary New'!34:34) -> 742.4 | ... AP34: =SUMIF('Daily Summary New'!$3:$3,AP$4,'Daily Summary New'!34:34) -> 0 | AR34: =SUM(C34:AP34) -> 99628.8 | AS34: =+AR34/SUM(AR34:AR35) -> 0.83084929
A35: Waste Pcs Packing | B35: =SUMIF('Daily Summary New'!$3:$3,B$4,'Daily Summary New'!35:35) -> 0 | C35: =SUMIF('Daily Summary New'!$3:$3,C$4,'Daily Summary New'!35:35) -> 0 | D35: =SUMIF('Daily Summary New'!$3:$3,D$4,'Daily Summary New'!35:35) -> 0 | E35: =SUMIF('Daily Summary New'!$3:$3,E$4,'Daily Summary New'!35:35) -> 0 | F35: =SUMIF('Daily Summary New'!$3:$3,F$4,'Daily Summary New'!35:35) -> 0 | G35: =SUMIF('Daily Summary New'!$3:$3,G$4,'Daily Summary New'!35:35) -> 0 | H35: =SUMIF('Daily Summary New'!$3:$3,H$4,'Daily Summary New'!35:35) -> 0 | I35: =SUMIF('Daily Summary New'!$3:$3,I$4,'Daily Summary New'!35:35) -> 0 | ... AP35: =SUMIF('Daily Summary New'!$3:$3,AP$4,'Daily Summary New'!35:35) -> 0 | AR35: =SUM(C35:AP35) -> 20283.2 | AS35: =+AR35/SUM(AR34:AR35) -> 0.16915071
A36: Waste % (v Produced) | B36: =IFERROR(SUM(B34:B35)/B25,"") | C36: =IFERROR(SUM(C34:C35)/C25,"") | D36: =IFERROR(SUM(D34:D35)/D25,"") | E36: =IFERROR(SUM(E34:E35)/E25,"") | F36: =IFERROR(SUM(F34:F35)/F25,"") | G36: =IFERROR(SUM(G34:G35)/G25,"") | H36: =IFERROR(SUM(H34:H35)/H25,"") -> 1 | I36: =IFERROR(SUM(I34:I35)/I25,"") -> 0.04080825 | ... AP36: =IFERROR(SUM(AP34:AP35)/AP25,"") | AR36: =IFERROR(SUM(AR34:AR35)/AR25,"") -> 0.10829617
A38: SD Backlog | Y38: ='Daily Summary New'!DM38 -> 115441.17
A39: Bao Backlog | Y39: ='Daily Summary New'!DM39 -> 34922.5
A43: Total OH
A44: Chicken SD | X44: =+X56+X68 -> 155640
A45: Pork SD | X45: =+X57+X69 -> 167700
A46: Chili Crisp SD | X46: =+X58+X70 -> 0
A47: Saucy Chicken SD | X47: =+X59+X71 -> 60000
A48: BBQ Pork Bao FS | X48: =+X60+X72 -> 38950
A49: BBQ Pork Bao 2-Pack | X49: =+X61+X73 -> 0
A50: BBQ Pork Bao 4-Pack | X50: =+X62+X74 -> 186752
A51: Teriyaki Chicken Bao 4-Pack | X51: =+X63+X75 -> 0
A52: Honey Chicken Mini Bao | X52: =+X64+X76 -> 37400
A53: Chili Crisp Mini Bao | X53: =+X65+X77 -> 33992
A55: FG OH (End Week) | C55: Cases | D55: Pieces
A56: Chicken SD | C56: =+D56/60 -> 3029 | D56: =+S56 -> 181740 | L56: =38*126*60+24*60+125*60+1032*60 -> 358140 | M56: 448620 | N56: =1792*60+(30*126*60) -> 334320 | O56: =1792*60 -> 107520 | P56: 263580 | R56: =4393*60 -> 263580 | S56: =3029*60 -> 181740 | U56: =3710*60 -> 222600 | V56: =4051*60 -> 243060 | W56: =6382*60 -> 382920 | X56: 155640
...

Sheet Daily Summary New
B1: =+TEXT(B4,"ddd") -> Mon | C1: =+TEXT(C4,"ddd") -> Tue | D1: =+TEXT(D4,"ddd") -> Wed | E1: =+TEXT(E4,"ddd") -> Thu | F1: =+TEXT(F4,"ddd") -> Mon | G1: =+TEXT(G4,"ddd") -> Tue | H1: =+TEXT(H4,"ddd") -> Wed | I1: =+TEXT(I4,"ddd") -> Thu | ... GK1: =+TEXT(GK4,"ddd") -> Wed
B2: 3 | C2: 3 | D2: 3 | E2: 3 | F2: 4 | G2: 4 | H2: 4 | I2: 4 | J2: 4 | K2: 4 | L2: 4 | M2: 4 | N2: 4 | O2: 4 | P2: 4 | Q2: 4 | R2: 4 | S2: 4 | T2: 4 | U2: 4 | V2: 4 | W2: 4 | X2: 4 | Y2: 4 | Z2: 4 | AA2: 4 | AB2: 4 | AC2: 4 | AD2: 5 | AE2: 5 | AF2: 5 | AG2: 5 | AH2: 5 | AI2: 5 | AJ2: 5 | AK2: 5 | AL2: 5 | AM2: 5 | AN2: 5 | AO2: 5 | AP2: 5 | AQ2: 5 | AR2: 5 | AS2: 5 | AT2: 5 | AU2: 5 | AV2: 5 | AW2: 5 | AX2: 6 | AY2: 6 | AZ2: 6 | BA2: 6 | BB2: 6 | BC2: 6 | BD2: 6 | BE2: 6 | BF2: 6 | BG2: 6 | BH2: 6 | BI2: 6 | BJ2: 6 | BK2: 6 | BL2: 6 | BM2: 6 | BN2: 6 | BO2: 6 | BP2: 6 | BQ2: 6 | BR2: 7 | BS2: 7 | BT2: 7 | BU2: 7 | BV2: 7 | BW2: 7 | BX2: 7 | BY2: 7 | BZ2: 7 | CA2: 7 | CB2: 7 | CC2: 7 | CD2: 7 | CE2: 7 | CF2: 7 | CG2: 7 | CH2: 7 | CI2: 7 | CJ2: 7 | CK2: 7 | CL2: 7 | CM2: 7 | CN2: 7 | CO2: 7 | CP2: 8 | CQ2: 8 | CR2: 8 | CS2: 8 | CT2: 8 | CU2: 8 | CV2: 8 | CW2: 8 | CX2: 8 | CY2: 8 | CZ2: 8 | DA2: 8 | DB2: 8 | DC2: 8 | DD2: 8 | DE2: 8 | DF2: 8 | DG2: 8 | DH2: 8 | DI2: 8 | DJ2: 9 | DK2: 9 | DL2: 9 | DM2: 9 | DN2: 9 | DO2: 9 | DP2: 9 | DQ2: 9 | DR2: 9 | DS2: 9 | DT2: 9 | DU2: 9 | DV2: 9 | DW2: 9 | DX2: 9 | DY2: 9 | DZ2: 9 | EA2: 9 | EB2: 9 | EC2: 10 | ED2: 10 | EE2: 10 | EF2: 10 | EG2: 10 | EH2: 10 | EI2: 10 | EJ2: 10 | EK2: 10 | EL2: 10 | EM2: 10 | EN2: 10 | EO2: 10 | EP2: 10 | EQ2: 10 | ER2: 10 | ES2: 10 | ET2: 10 | EU2: 10 | EV2: 10 | EW2: 10 | EX2: 10 | EY2: 10 | EZ2: 10 | FA2: 10 | FB2: 11 | FC2: 11 | FD2: 11 | FE2: 11 | FF2: 11 | FG2: 11 | FH2: 11 | FI2: 11 | FJ2: 11 | FK2: 11 | FL2: 11 | FM2: 11 | FN2: 11 | FO2: 11 | FP2: 11 | FQ2: 11 | FR2: 11 | FS2: 11 | FT2: 12 | FU2: 12 | FV2: 12 | FW2: 12 | FX2: 12 | FY2: 12 | FZ2: 12 | GA2: 12 | GB2: 12 | GC2: 12 | GD2: 12 | GE2: 12 | GF2: 12 | GG2: 12 | GH2: 12 | GI2: 12 | GJ2: 12 | GK2: 12
B3: =+WEEKNUM(B4) -> 13 | C3: =+WEEKNUM(C4) -> 13 | D3: =+WEEKNUM(D4) -> 13 | E3: =+WEEKNUM(E4) -> 13 | F3: =+WEEKNUM(F4) -> 14 | G3: =+WEEKNUM(G4) -> 14 | H3: =+WEEKNUM(H4) -> 14 | I3: =+WEEKNUM(I4) -> 14 | ... GK3: =+WEEKNUM(GK4) -> 52
B4: 46104 | C4: 46105 | D4: 46106 | E4: 46107 | F4: 46111 | G4: =WORKDAY.INTL(F4,1,,'Don''t Change'!$A$2:$A$7) -> 46112 | H4: =WORKDAY.INTL(G4,1,,'Don''t Change'!$A$2:$A$7) -> 46113 | I4: =WORKDAY.INTL(H4,1,,'Don''t Change'!$A$2:$A$7) -> 46114 | J4: =WORKDAY.INTL(I4,1,,'Don''t Change'!$A$2:$A$7) -> 46115 | K4: =WORKDAY.INTL(J4,1,,'Don''t Change'!$A$2:$A$7) -> 46118 | L4: =WORKDAY.INTL(K4,1,,'Don''t Change'!$A$2:$A$7) -> 46119 | M4: =WORKDAY.INTL(L4,1,,'Don''t Change'!$A$2:$A$7) -> 46120 | N4: =WORKDAY.INTL(M4,1,,'Don''t Change'!$A$2:$A$7) -> 46121 | ... GK4: =WORKDAY.INTL(GJ4,1,,'Don''t Change'!$A$2:$A$7) -> 46379
A6: SD Ramp Plan | B6: =IF(B1="Fri",0,SUMIF('Ramp Up Plan'!$3:$3,B$2,'Ramp Up Plan'!96:96)) -> 0 | C6: =IF(C1="Fri",0,SUMIF('Ramp Up Plan'!$3:$3,C$2,'Ramp Up Plan'!96:96)) -> 0 | D6: =IF(D1="Fri",0,SUMIF('Ramp Up Plan'!$3:$3,D$2,'Ramp Up Plan'!96:96)) -> 0 | E6: =IF(E1="Fri",0,SUMIF('Ramp Up Plan'!$3:$3,E$2,'Ramp Up Plan'!96:96)) -> 0 | F6: =IF(F1="Fri",0,SUMIF('Ramp Up Plan'!$3:$3,F$2,'Ramp Up Plan'!96:96)) -> 11520 | G6: =IF(G1="Fri",0,SUMIF('Ramp Up Plan'!$3:$3,G2,'Ramp Up Plan'!96:96)) -> 11520 | H6: =IF(H1="Fri",0,SUMIF('Ramp Up Plan'!$3:$3,H2,'Ramp Up Plan'!96:96)) -> 11520 | I6: =IF(I1="Fri",0,SUMIF('Ramp Up Plan'!$3:$3,I2,'Ramp Up Plan'!96:96)) -> 11520 | J6: =IF(J1="Fri",0,SUMIF('Ramp Up Plan'!$3:$3,J2,'Ramp Up Plan'!96:96)) -> 0 | K6: =IF(K1="Fri",0,SUMIF('Ramp Up Plan'!$3:$3,K2,'Ramp Up Plan'!96:96)) -> 11520 | L6: =IF(L1="Fri",0,SUMIF('Ramp Up Plan'!$3:$3,L2,'Ramp Up Plan'!96:96)) -> 11520 | M6: =IF(M1="Fri",0,SUMIF('Ramp Up Plan'!$3:$3,M2,'Ramp Up Plan'!96:96)) -> 11520 | N6: =IF(N1="Fri",0,SUMIF('Ramp Up Plan'!$3:$3,N2,'Ramp Up Plan'!96:96)) -> 11520 | ... AW6: =IF(AW1="Fri",0,SUMIF('Ramp Up Plan'!$3:$3,AW2,'Ramp Up Plan'!96:96)) -> 0 | AX6: =SUMIF('Ramp Up Plan'!$3:$3,AX2,'Ramp Up Plan'!96:96) -> 57600 | AY6: =SUMIF('Ramp Up Plan'!$3:$3,AY2,'Ramp Up Plan'!96:96) -> 57600 | AZ6: =SUMIF('Ramp Up Plan'!$3:$3,AZ2,'Ramp Up Plan'!96:96) -> 57600 | BA6: =SUMIF('Ramp Up Plan'!$3:$3,BA2,'Ramp Up Plan'!96:96) -> 57600 | BB6: =SUMIF('Ramp Up Plan'!$3:$3,BB2,'Ramp Up Plan'!96:96) -> 57600 | BC6: =SUMIF('Ramp Up Plan'!$3:$3,BC2,'Ramp Up Plan'!96:96) -> 57600 | BD6: =SUMIF('Ramp Up Plan'!$3:$3,BD2,'Ramp Up Plan'!96:96) -> 57600 | BE6: =SUMIF('Ramp Up Plan'!$3:$3,BE2,'Ramp Up Plan'!96:96) -> 57600 | ... GK6: =SUMIF('Ramp Up Plan'!$3:$3,GK2,'Ramp Up Plan'!96:96) -> 98496
A7: New SD Plant Plan | B7: =+B6 -> 0 | C7: =+C6 -> 0 | D7: =+D6 -> 0 | E7: =+E6 -> 0 | CP7: =SUMIF('New Plant SD Plan'!$A:$A,CP4,'New Plant SD Plan'!$E:$E) -> 80000 | CQ7: =SUMIF('New Plant SD Plan'!$A:$A,CQ4,'New Plant SD Plan'!$E:$E) -> 80000 | CR7: =SUMIF('New Plant SD Plan'!$A:$A,CR4,'New Plant SD Plan'!$E:$E) -> 80000 | CS7: =SUMIF('New Plant SD Plan'!$A:$A,CS4,'New Plant SD Plan'!$E:$E) -> 80000 | CT7: =SUMIF('New Plant SD Plan'!$A:$A,CT4,'New Plant SD Plan'!$E:$E) -> 0 | CU7: =SUMIF('New Plant SD Plan'!$A:$A,CU4,'New Plant SD Plan'!$E:$E) -> 80000 | CV7: =SUMIF('New Plant SD Plan'!$A:$A,CV4,'New Plant SD Plan'!$E:$E) -> 80000 | CW7: =SUMIF('New Plant SD Plan'!$A:$A,CW4,'New Plant SD Plan'!$E:$E) -> 80000 | ... GK7: =SUMIF('New Plant SD Plan'!$A:$A,GK4,'New Plant SD Plan'!$E:$E) -> 160000
A9: SD Produced | B9: =SUMIF('Raw Data - Production'!$A:$A,B$4,'Raw Data - Production'!$D:$D)+SUMIF('Raw Data - Production'!$A:$A,B$4,'Raw Data - Production'!$E:$E)+SUMIF('Raw Data - Production'!$A:$A,B$4,'Raw Data - Production'!$F:$F)+SUMIF('Raw Data - Production'!$A:$A,B4,'Raw Data - Production'!$Q:$Q) -> 10200 | C9: =SUMIF('Raw Data - Production'!$A:$A,C$4,'Raw Data - Production'!$D:$D)+SUMIF('Raw Data - Production'!$A:$A,C$4,'Raw Data - Production'!$E:$E)+SUMIF('Raw Data - Production'!$A:$A,C$4,'Raw Data - Production'!$F:$F)+SUMIF('Raw Data - Production'!$A:$A,C4,'Raw Data - Production'!$Q:$Q) -> 23340 | D9: =SUMIF('Raw Data - Production'!$A:$A,D$4,'Raw Data - Production'!$D:$D)+SUMIF('Raw Data - Production'!$A:$A,D$4,'Raw Data - Production'!$E:$E)+SUMIF('Raw Data - Production'!$A:$A,D$4,'Raw Data - Production'!$F:$F)+SUMIF('Raw Data - Production'!$A:$A,D4,'Raw Data - Production'!$Q:$Q) -> 9420 | E9: =SUMIF('Raw Data - Production'!$A:$A,E$4,'Raw Data - Production'!$D:$D)+SUMIF('Raw Data - Production'!$A:$A,E$4,'Raw Data - Production'!$E:$E)+SUMIF('Raw Data - Production'!$A:$A,E$4,'Raw Data - Production'!$F:$F)+SUMIF('Raw Data - Production'!$A:$A,E4,'Raw Data - Production'!$Q:$Q) -> 33360 | F9: =SUMIF('Raw Data - Production'!$A:$A,F$4,'Raw Data - Production'!$D:$D)+SUMIF('Raw Data - Production'!$A:$A,F$4,'Raw Data - Production'!$E:$E)+SUMIF('Raw Data - Production'!$A:$A,F$4,'Raw Data - Production'!$F:$F)+SUMIF('Raw Data - Production'!$A:$A,F4,'Raw Data - Production'!$Q:$Q) -> 34860 | G9: =SUMIF('Raw Data - Production'!$A:$A,G$4,'Raw Data - Production'!$D:$D)+SUMIF('Raw Data - Production'!$A:$A,G$4,'Raw Data - Production'!$E:$E)+SUMIF('Raw Data - Production'!$A:$A,G$4,'Raw Data - Production'!$F:$F)+SUMIF('Raw Data - Production'!$A:$A,G4,'Raw Data - Production'!$Q:$Q) -> 33480 | H9: =SUMIF('Raw Data - Production'!$A:$A,H$4,'Raw Data - Production'!$D:$D)+SUMIF('Raw Data - Production'!$A:$A,H$4,'Raw Data - Production'!$E:$E)+SUMIF('Raw Data - Production'!$A:$A,H$4,'Raw Data - Production'!$F:$F)+SUMIF('Raw Data - Production'!$A:$A,H4,'Raw Data - Production'!$Q:$Q) -> 52620 | I9: =SUMIF('Raw Data - Production'!$A:$A,I$4,'Raw Data - Production'!$D:$D)+SUMIF('Raw Data - Production'!$A:$A,I$4,'Raw Data - Production'!$E:$E)+SUMIF('Raw Data - Production'!$A:$A,I$4,'Raw Data - Production'!$F:$F)+SUMIF('Raw Data - Production'!$A:$A,I4,'Raw Data - Production'!$Q:$Q) -> 34080 | ... DL9: =SUMIF('Raw Data - Production'!$A:$A,DL$4,'Raw Data - Production'!$D:$D)+SUMIF('Raw Data - Production'!$A:$A,DL$4,'Raw Data - Production'!$E:$E)+SUMIF('Raw Data - Production'!$A:$A,DL$4,'Raw Data - Production'!$F:$F)+SUMIF('Raw Data - Production'!$A:$A,DL4,'Raw Data - Production'!$Q:$Q) -> 50850.37 | DM9: =SUMIF('Raw Data - Production'!$A:$A,DM$4,'Raw Data - Production'!$D:$D)+SUMIF('Raw Data - Production'!$A:$A,DM$4,'Raw Data - Production'!$E:$E)+SUMIF('Raw Data - Production'!$A:$A,DM$4,'Raw Data - Production'!$F:$F) -> 168387 | DN9: =SUMIF('Raw Data - Production'!$A:$A,DN$4,'Raw Data - Production'!$D:$D)+SUMIF('Raw Data - Production'!$A:$A,DN$4,'Raw Data - Production'!$E:$E)+SUMIF('Raw Data - Production'!$A:$A,DN$4,'Raw Data - Production'!$F:$F) -> 0 | DO9: =SUMIF('Raw Data - Production'!$A:$A,DO$4,'Raw Data - Production'!$D:$D)+SUMIF('Raw Data - Production'!$A:$A,DO$4,'Raw Data - Production'!$E:$E)+SUMIF('Raw Data - Production'!$A:$A,DO$4,'Raw Data - Production'!$F:$F) -> 0 | DP9: =SUMIF('Raw Data - Production'!$A:$A,DP$4,'Raw Data - Production'!$D:$D)+SUMIF('Raw Data - Production'!$A:$A,DP$4,'Raw Data - Production'!$E:$E)+SUMIF('Raw Data - Production'!$A:$A,DP$4,'Raw Data - Production'!$F:$F) -> 0 | DQ9: =SUMIF('Raw Data - Production'!$A:$A,DQ$4,'Raw Data - Production'!$D:$D)+SUMIF('Raw Data - Production'!$A:$A,DQ$4,'Raw Data - Production'!$E:$E)+SUMIF('Raw Data - Production'!$A:$A,DQ$4,'Raw Data - Production'!$F:$F) -> 0 | DR9: =SUMIF('Raw Data - Production'!$A:$A,DR$4,'Raw Data - Production'!$D:$D)+SUMIF('Raw Data - Production'!$A:$A,DR$4,'Raw Data - Production'!$E:$E)+SUMIF('Raw Data - Production'!$A:$A,DR$4,'Raw Data - Production'!$F:$F) -> 0 | DS9: =SUMIF('Raw Data - Production'!$A:$A,DS$4,'Raw Data - Production'!$D:$D)+SUMIF('Raw Data - Production'!$A:$A,DS$4,'Raw Data - Production'!$E:$E)+SUMIF('Raw Data - Production'!$A:$A,DS$4,'Raw Data - Production'!$F:$F) -> 0 | DT9: =SUMIF('Raw Data - Production'!$A:$A,DT$4,'Raw Data - Production'!$D:$D)+SUMIF('Raw Data - Production'!$A:$A,DT$4,'Raw Data - Production'!$E:$E)+SUMIF('Raw Data - Production'!$A:$A,DT$4,'Raw Data - Production'!$F:$F) -> 0 | ... GK9: =SUMIF('Raw Data - Production'!$A:$A,GK$4,'Raw Data - Production'!$D:$D)+SUMIF('Raw Data - Production'!$A:$A,GK$4,'Raw Data - Production'!$E:$E)+SUMIF('Raw Data - Production'!$A:$A,GK$4,'Raw Data - Production'!$F:$F) -> 0 | GL9: =SUM(F9:GK9) -> 5682915.2
A10: SD Packed | B10: =SUMIF('Raw Data - Packing'!$A:$A,B$4,'Raw Data - Packing'!$D:$D) -> 10200 | C10: =SUMIF('Raw Data - Packing'!$A:$A,C$4,'Raw Data - Packing'!$D:$D) -> 23340 | D10: =SUMIF('Raw Data - Packing'!$A:$A,D$4,'Raw Data - Packing'!$D:$D) -> 9420 | E10: =SUMIF('Raw Data - Packing'!$A:$A,E$4,'Raw Data - Packing'!$D:$D) -> 33360 | F10: =SUMIF('Raw Data - Packing'!$A:$A,F$4,'Raw Data - Packing'!$D:$D) -> 34860 | G10: =SUMIF('Raw Data - Packing'!$A:$A,G$4,'Raw Data - Packing'!$D:$D) -> 33480 | H10: =SUMIF('Raw Data - Packing'!$A:$A,H$4,'Raw Data - Packing'!$D:$D) -> 52620 | I10: =SUMIF('Raw Data - Packing'!$A:$A,I$4,'Raw Data - Packing'!$D:$D) -> 34080 | ... GK10: =SUMIF('Raw Data - Packing'!$A:$A,GK$4,'Raw Data - Packing'!$D:$D) -> 0 | GL10: =SUM(F10:GK10) -> 5121932
A13: Produced v Ramp Plan | B13: =+B9-B6 -> 10200 | C13: =+C9-C6 -> 23340 | D13: =+D9-D6 -> 9420 | E13: =+E9-E6 -> 33360 | F13: =+F9-F6 -> 23340 | G13: =+G9-G6 -> 21960 | H13: =+H9-H6 -> 41100 | I13: =+I9-I6 -> 22560 | ... DJ13: =+DJ9-DJ6 -> 15801.086 | GL13: =SUM(B13:GK13) -> 71130.341
A14: Packed v Ramp Plan | B14: =+B10-B6 -> 10200 | C14: =+C10-C6 -> 23340 | D14: =+D10-D6 -> 9420 | E14: =+E10-E6 -> 33360 | F14: =+F10-F6 -> 23340 | G14: =+G10-G6 -> 21960 | H14: =+H10-H6 -> 41100 | I14: =+I10-I6 -> 22560 | ... DJ14: =+DJ10-DJ6 -> -74746 | GL14: =SUM(B14:GK14) -> -576878.8
A15: Produced v New Plant Plan | CP15: =+CP9-CP7 -> -4566.5185 | CQ15: =+CQ9-CQ7 -> 18551.704 | CR15: =+CR9-CR7 -> 11701.136 | CS15: =+CS9-CS7 -> -21556.543 | CT15: =+CT9-CT7 -> 0 | CU15: =+CU9-CU7 -> -7977.0864 | CV15: =+CV9-CV7 -> 10269.63 | CW15: =+CW9-CW7 -> 14670.617 | ... DJ15: =+DJ9-DJ7 -> 114297.09 | GL15: =SUM(B15:GK15) -> 67504.198
A16: Packed v New Plant Plan | CP16: =+CP10-CP7 -> -20060 | CQ16: =+CQ10-CQ7 -> -1220 | CR16: =+CR10-CR7 -> -27080 | CS16: =+CS10-CS7 -> -36440 | CT16: =+CT10-CT7 -> 0 | CU16: =+CU10-CU7 -> -16220 | CV16: =+CV10-CV7 -> -31940 | CW16: =+CW10-CW7 -> -19520 | ... DJ16: =+DJ10-DJ7 -> 23750 | GL16: =SUM(B16:GK16) -> -229130
A18: Waste Pcs Production | B18: =SUMIF('Raw Data - Production'!$A:$A,B$4,'Raw Data - Production'!$Q:$Q) -> 0 | C18: =SUMIF('Raw Data - Production'!$A:$A,C$4,'Raw Data - Production'!$Q:$Q) -> 0 | D18: =SUMIF('Raw Data - Production'!$A:$A,D$4,'Raw Data - Production'!$Q:$Q) -> 0 | E18: =SUMIF('Raw Data - Production'!$A:$A,E$4,'Raw Data - Production'!$Q:$Q) -> 0 | F18: =SUMIF('Raw Data - Production'!$A:$A,F$4,'Raw Data - Production'!$Q:$Q) -> 0 | G18: =SUMIF('Raw Data - Production'!$A:$A,G$4,'Raw Data - Production'!$Q:$Q) -> 0 | H18: =SUMIF('Raw Data - Production'!$A:$A,H$4,'Raw Data - Production'!$Q:$Q) -> 0 | I18: =SUMIF('Raw Data - Production'!$A:$A,I$4,'Raw Data - Production'!$Q:$Q) -> 0 | ... GK18: =SUMIF('Raw Data - Production'!$A:$A,GK$4,'Raw Data - Production'!$Q:$Q) -> 0 | GL18: =SUM(F18:GK18) -> 370968.18 | GM18: =+GL18/SUM($GL$18:$GL$19) -> 0.90260813
A19: Waste Pcs Packing | B19: =+SUMIF('Raw Data - Packing'!$A:$A,B$4,'Raw Data - Packing'!$R:$R) -> 0 | C19: =+SUMIF('Raw Data - Packing'!$A:$A,C$4,'Raw Data - Packing'!$R:$R) -> 0 | D19: =+SUMIF('Raw Data - Packing'!$A:$A,D$4,'Raw Data - Packing'!$R:$R) -> 0 | E19: =+SUMIF('Raw Data - Packing'!$A:$A,E$4,'Raw Data - Packing'!$R:$R) -> 0 | F19: =+SUMIF('Raw Data - Packing'!$A:$A,F$4,'Raw Data - Packing'!$R:$R) -> 0 | G19: =+SUMIF('Raw Data - Packing'!$A:$A,G$4,'Raw Data - Packing'!$R:$R) -> 0 | H19: =+SUMIF('Raw Data - Packing'!$A:$A,H$4,'Raw Data - Packing'!$R:$R) -> 0 | I19: =+SUMIF('Raw Data - Packing'!$A:$A,I$4,'Raw Data - Packing'!$R:$R) -> 0 | ... GK19: =+SUMIF('Raw Data - Packing'!$A:$A,GK$4,'Raw Data - Packing'!$R:$R) -> 0 | GL19: =SUM(F19:GK19) -> 40027.654 | GM19: =+GL19/SUM($GL$18:$GL$19) -> 0.097391874
A20: Waste % (v Produced) | B20: =IFERROR(SUM(B18:B19)/B9,"") -> 0 | C20: =IFERROR(SUM(C18:C19)/C9,"") -> 0 | D20: =IFERROR(SUM(D18:D19)/D9,"") -> 0 | E20: =IFERROR(SUM(E18:E19)/E9,"") -> 0 | F20: =IFERROR(SUM(F18:F19)/F9,"") -> 0 | G20: =IFERROR(SUM(G18:G19)/G9,"") -> 0 | H20: =IFERROR(SUM(H18:H19)/H9,"") -> 0 | I20: =IFERROR(SUM(I18:I19)/I9,"") -> 0 | ... GL20: =IFERROR(SUM(GL18:GL19)/GL9,"") -> 0.072321303
A22: Bao Ramp Plan | B22: =IF(B15="Fri",0,SUMIF('Ramp Up Plan'!$3:$3,B$2,'Ramp Up Plan'!84:84)) -> 0 | C22: =IF(C15="Fri",0,SUMIF('Ramp Up Plan'!$3:$3,C$2,'Ramp Up Plan'!84:84)) -> 0 | D22: =IF(D15="Fri",0,SUMIF('Ramp Up Plan'!$3:$3,D$2,'Ramp Up Plan'!84:84)) -> 0 | E22: =IF(E15="Fri",0,SUMIF('Ramp Up Plan'!$3:$3,E$2,'Ramp Up Plan'!84:84)) -> 0 | F22: =IF(F15="Fri",0,SUMIF('Ramp Up Plan'!$3:$3,F$2,'Ramp Up Plan'!84:84)) -> 11880 | G22: =IF(G15="Fri",0,SUMIF('Ramp Up Plan'!$3:$3,G$2,'Ramp Up Plan'!84:84)) -> 11880 | H22: =IF(H15="Fri",0,SUMIF('Ramp Up Plan'!$3:$3,H$2,'Ramp Up Plan'!84:84)) -> 11880 | I22: =IF(I15="Fri",0,SUMIF('Ramp Up Plan'!$3:$3,I$2,'Ramp Up Plan'!84:84)) -> 11880 | ... DN22: =IF(DN15="Fri",0,SUMIF('Ramp Up Plan'!$3:$3,DN$2,'Ramp Up Plan'!84:84)) -> 108590.62
A23: New Bao Plant Plan | CM23: =SUMIF('New Plant SD Plan'!$A:$A,CM20,'New Plant SD Plan'!$E:$E) -> 0 | CN23: =SUMIF('New Plant Bao Plan'!$A:$A,CN4,'New Plant Bao Plan'!$E:$E) -> 0 | CO23: =SUMIF('New Plant Bao Plan'!$A:$A,CO4,'New Plant Bao Plan'!$E:$E) -> 0 | CP23: =SUMIF('New Plant Bao Plan'!$A:$A,CP4,'New Plant Bao Plan'!$E:$E) -> 0 | CQ23: =SUMIF('New Plant Bao Plan'!$A:$A,CQ4,'New Plant Bao Plan'!$E:$E) -> 0 | CR23: =SUMIF('New Plant Bao Plan'!$A:$A,CR4,'New Plant Bao Plan'!$E:$E) -> 0 | CS23: =SUMIF('New Plant Bao Plan'!$A:$A,CS4,'New Plant Bao Plan'!$E:$E) -> 0 | CT23: =SUMIF('New Plant Bao Plan'!$A:$A,CT4,'New Plant Bao Plan'!$E:$E) -> 0 | CU23: =SUMIF('New Plant Bao Plan'!$A:$A,CU4,'New Plant Bao Plan'!$E:$E) -> 0 | ... GK23: =SUMIF('New Plant Bao Plan'!$A:$A,GK4,'New Plant Bao Plan'!$E:$E) -> 75000 | GL23: =SUM(CM23:GK23) -> 6135000
A25: Bao Produced | B25: =SUMIF('Raw Data - Production'!$A:$A,B$4,'Raw Data - Production'!$G:$G)+SUMIF('Raw Data - Production'!$A:$A,B$4,'Raw Data - Production'!$H:$H)+SUMIF('Raw Data - Production'!$A:$A,B$4,'Raw Data - Production'!$I:$I)+SUMIF('Raw Data - Production'!$A:$A,B4,'Raw Data - Production'!$R:$R) -> 0 | C25: =SUMIF('Raw Data - Production'!$A:$A,C$4,'Raw Data - Production'!$G:$G)+SUMIF('Raw Data - Production'!$A:$A,C$4,'Raw Data - Production'!$H:$H)+SUMIF('Raw Data - Production'!$A:$A,C$4,'Raw Data - Production'!$I:$I)+SUMIF('Raw Data - Production'!$A:$A,C4,'Raw Data - Production'!$R:$R) -> 0 | D25: =SUMIF('Raw Data - Production'!$A:$A,D$4,'Raw Data - Production'!$G:$G)+SUMIF('Raw Data - Production'!$A:$A,D$4,'Raw Data - Production'!$H:$H)+SUMIF('Raw Data - Production'!$A:$A,D$4,'Raw Data - Production'!$I:$I)+SUMIF('Raw Data - Production'!$A:$A,D4,'Raw Data - Production'!$R:$R) -> 0 | E25: =SUMIF('Raw Data - Production'!$A:$A,E$4,'Raw Data - Production'!$G:$G)+SUMIF('Raw Data - Production'!$A:$A,E$4,'Raw Data - Production'!$H:$H)+SUMIF('Raw Data - Production'!$A:$A,E$4,'Raw Data - Production'!$I:$I)+SUMIF('Raw Data - Production'!$A:$A,E4,'Raw Data - Production'!$R:$R) -> 0 | F25: =SUMIF('Raw Data - Production'!$A:$A,F$4,'Raw Data - Production'!$G:$G)+SUMIF('Raw Data - Production'!$A:$A,F$4,'Raw Data - Production'!$H:$H)+SUMIF('Raw Data - Production'!$A:$A,F$4,'Raw Data - Production'!$I:$I)+SUMIF('Raw Data - Production'!$A:$A,F4,'Raw Data - Production'!$R:$R) -> 0 | G25: =SUMIF('Raw Data - Production'!$A:$A,G$4,'Raw Data - Production'!$G:$G)+SUMIF('Raw Data - Production'!$A:$A,G$4,'Raw Data - Production'!$H:$H)+SUMIF('Raw Data - Production'!$A:$A,G$4,'Raw Data - Production'!$I:$I)+SUMIF('Raw Data - Production'!$A:$A,G4,'Raw Data - Production'!$R:$R) -> 0 | H25: =SUMIF('Raw Data - Production'!$A:$A,H$4,'Raw Data - Production'!$G:$G)+SUMIF('Raw Data - Production'!$A:$A,H$4,'Raw Data - Production'!$H:$H)+SUMIF('Raw Data - Production'!$A:$A,H$4,'Raw Data - Production'!$I:$I)+SUMIF('Raw Data - Production'!$A:$A,H4,'Raw Data - Production'!$R:$R) -> 0 | I25: =SUMIF('Raw Data - Production'!$A:$A,I$4,'Raw Data - Production'!$G:$G)+SUMIF('Raw Data - Production'!$A:$A,I$4,'Raw Data - Production'!$H:$H)+SUMIF('Raw Data - Production'!$A:$A,I$4,'Raw Data - Production'!$I:$I)+SUMIF('Raw Data - Production'!$A:$A,I4,'Raw Data - Production'!$R:$R) -> 0 | ... DL25: =SUMIF('Raw Data - Production'!$A:$A,DL$4,'Raw Data - Production'!$G:$G)+SUMIF('Raw Data - Production'!$A:$A,DL$4,'Raw Data - Production'!$H:$H)+SUMIF('Raw Data - Production'!$A:$A,DL$4,'Raw Data - Production'!$I:$I)+SUMIF('Raw Data - Production'!$A:$A,DL4,'Raw Data - Production'!$R:$R) -> 1995 | DM25: =SUMIF('Raw Data - Production'!$A:$A,DM$4,'Raw Data - Production'!$G:$G)+SUMIF('Raw Data - Production'!$A:$A,DM$4,'Raw Data - Production'!$H:$H)+SUMIF('Raw Data - Production'!$A:$A,DM$4,'Raw Data - Production'!$I:$I) -> 0 | DN25: =SUMIF('Raw Data - Production'!$A:$A,DN$4,'Raw Data - Production'!$G:$G)+SUMIF('Raw Data - Production'!$A:$A,DN$4,'Raw Data - Production'!$H:$H)+SUMIF('Raw Data - Production'!$A:$A,DN$4,'Raw Data - Production'!$I:$I) -> 0 | DO25: =SUMIF('Raw Data - Production'!$A:$A,DO$4,'Raw Data - Production'!$G:$G)+SUMIF('Raw Data - Production'!$A:$A,DO$4,'Raw Data - Production'!$H:$H)+SUMIF('Raw Data - Production'!$A:$A,DO$4,'Raw Data - Production'!$I:$I) -> 0 | DP25: =SUMIF('Raw Data - Production'!$A:$A,DP$4,'Raw Data - Production'!$G:$G)+SUMIF('Raw Data - Production'!$A:$A,DP$4,'Raw Data - Production'!$H:$H)+SUMIF('Raw Data - Production'!$A:$A,DP$4,'Raw Data - Production'!$I:$I) -> 0 | DQ25: =SUMIF('Raw Data - Production'!$A:$A,DQ$4,'Raw Data - Production'!$G:$G)+SUMIF('Raw Data - Production'!$A:$A,DQ$4,'Raw Data - Production'!$H:$H)+SUMIF('Raw Data - Production'!$A:$A,DQ$4,'Raw Data - Production'!$I:$I) -> 0 | DR25: =SUMIF('Raw Data - Production'!$A:$A,DR$4,'Raw Data - Production'!$G:$G)+SUMIF('Raw Data - Production'!$A:$A,DR$4,'Raw Data - Production'!$H:$H)+SUMIF('Raw Data - Production'!$A:$A,DR$4,'Raw Data - Production'!$I:$I) -> 0 | DS25: =SUMIF('Raw Data - Production'!$A:$A,DS$4,'Raw Data - Production'!$G:$G)+SUMIF('Raw Data - Production'!$A:$A,DS$4,'Raw Data - Production'!$H:$H)+SUMIF('Raw Data - Production'!$A:$A,DS$4,'Raw Data - Production'!$I:$I) -> 0 | DT25: =SUMIF('Raw Data - Production'!$A:$A,DT$4,'Raw Data - Production'!$G:$G)+SUMIF('Raw Data - Production'!$A:$A,DT$4,'Raw Data - Production'!$H:$H)+SUMIF('Raw Data - Production'!$A:$A,DT$4,'Raw Data - Production'!$I:$I) -> 0 | ... GK25: =SUMIF('Raw Data - Production'!$A:$A,GK$4,'Raw Data - Production'!$G:$G)+SUMIF('Raw Data - Production'!$A:$A,GK$4,'Raw Data - Production'!$H:$H)+SUMIF('Raw Data - Production'!$A:$A,GK$4,'Raw Data - Production'!$I:$I) -> 0 | GL25: =SUM(F25:GK25) -> 1107259.8
A26: Bao Packed | B26: =SUMIF('Raw Data - Packing'!$A:$A,B4,'Raw Data - Packing'!$F:$F) -> 0 | C26: =SUMIF('Raw Data - Packing'!$A:$A,C4,'Raw Data - Packing'!$F:$F) -> 0 | D26: =SUMIF('Raw Data - Packing'!$A:$A,D4,'Raw Data - Packing'!$F:$F) -> 0 | E26: =SUMIF('Raw Data - Packing'!$A:$A,E4,'Raw Data - Packing'!$F:$F) -> 0 | F26: =SUMIF('Raw Data - Packing'!$A:$A,F4,'Raw Data - Packing'!$F:$F) -> 0 | G26: =SUMIF('Raw Data - Packing'!$A:$A,G4,'Raw Data - Packing'!$F:$F) -> 0 | H26: =SUMIF('Raw Data - Packing'!$A:$A,H4,'Raw Data - Packing'!$F:$F) -> 0 | I26: =SUMIF('Raw Data - Packing'!$A:$A,I4,'Raw Data - Packing'!$F:$F) -> 0 | ... GK26: =SUMIF('Raw Data - Packing'!$A:$A,GK4,'Raw Data - Packing'!$F:$F) -> 0 | GL26: =SUM(F26:GK26) -> 825127
A29: Produced v Ramp Plan | B29: =+B25-B22 -> 0 | C29: =+C25-C22 -> 0 | D29: =+D25-D22 -> 0 | E29: =+E25-E22 -> 0 | F29: =+F25-F22 -> -11880 | G29: =+G25-G22 -> -11880 | H29: =+H25-H22 -> -11880 | I29: =+I25-I22 -> -11880 | ... DJ29: =+DJ25-DJ22 -> -58644.625 | GL29: =SUM(B29:GK29) -> -5655789.4
A30: Packed v Ramp Plan | B30: =+B26-B22 -> 0 | C30: =+C26-C22 -> 0 | D30: =+D26-D22 -> 0 | E30: =+E26-E22 -> 0 | F30: =+F26-F22 -> -11880 | G30: =+G26-G22 -> -11880 | H30: =+H26-H22 -> -11880 | I30: =+I26-I22 -> -11880 | ... DJ30: =+DJ26-DJ22 -> -97390.625 | GL30: =SUM(B30:GK30) -> -5923607.6
A31: Produced v New Plant Plan | CP31: =+CP25-CP23 -> 49680.2 | CQ31: =+CQ25-CQ23 -> 37224 | CR31: =+CR25-CR23 -> 38270 | CS31: =+CS25-CS23 -> 38215.4 | CT31: =+CT25-CT23 -> 0 | CU31: =+CU25-CU23 -> 51938 | CV31: =+CV25-CV23 -> 45468.2 | CW31: =+CW25-CW23 -> 41774.6 | ... DJ31: =+DJ25-DJ23 -> -25054 | GL31: =SUM(B31:GK31) -> 272328.3
A32: Packed v New Plant Plan | CP32: =+CP26-CP23 -> 21600 | CQ32: =+CQ26-CQ23 -> 25920 | CR32: =+CR26-CR23 -> 21600 | CS32: =+CS26-CS23 -> 30240 | CT32: =+CT26-CT23 -> 0 | CU32: =+CU26-CU23 -> 30336 | CV32: =+CV26-CV23 -> 40550 | CW32: =+CW26-CW23 -> 28800 | ... DJ32: =+DJ26-DJ23 -> -63800 | GL32: =SUM(B32:GK32) -> 119602
A34: Waste Pcs Production | B34: =SUMIF('Raw Data - Production'!$A:$A,B$4,'Raw Data - Production'!$R:$R) -> 0 | C34: =SUMIF('Raw Data - Production'!$A:$A,C$4,'Raw Data - Production'!$R:$R) -> 0 | D34: =SUMIF('Raw Data - Production'!$A:$A,D$4,'Raw Data - Production'!$R:$R) -> 0 | E34: =SUMIF('Raw Data - Production'!$A:$A,E$4,'Raw Data - Production'!$R:$R) -> 0 | F34: =SUMIF('Raw Data - Production'!$A:$A,F$4,'Raw Data - Production'!$R:$R) -> 0 | G34: =SUMIF('Raw Data - Production'!$A:$A,G$4,'Raw Data - Production'!$R:$R) -> 0 | H34: =SUMIF('Raw Data - Production'!$A:$A,H$4,'Raw Data - Production'!$R:$R) -> 0 | I34: =SUMIF('Raw Data - Production'!$A:$A,I$4,'Raw Data - Production'!$R:$R) -> 0 | ... GK34: =SUMIF('Raw Data - Production'!$A:$A,GK$4,'Raw Data - Production'!$R:$R) -> 0 | GL34: =SUM(F34:GK34) -> 99628.8 | GM34: =+GL34/SUM($GL$34:$GL$35) -> 0.83084929
A35: Waste Pcs Packing | B35: =+SUMIF('Raw Data - Packing'!$A:$A,B$4,'Raw Data - Packing'!$S:$S) -> 0 | C35: =+SUMIF('Raw Data - Packing'!$A:$A,C$4,'Raw Data - Packing'!$S:$S) -> 0 | D35: =+SUMIF('Raw Data - Packing'!$A:$A,D$4,'Raw Data - Packing'!$S:$S) -> 0 | E35: =+SUMIF('Raw Data - Packing'!$A:$A,E$4,'Raw Data - Packing'!$S:$S) -> 0 | F35: =+SUMIF('Raw Data - Packing'!$A:$A,F$4,'Raw Data - Packing'!$S:$S) -> 0 | G35: =+SUMIF('Raw Data - Packing'!$A:$A,G$4,'Raw Data - Packing'!$S:$S) -> 0 | H35: =+SUMIF('Raw Data - Packing'!$A:$A,H$4,'Raw Data - Packing'!$S:$S) -> 0 | I35: =+SUMIF('Raw Data - Packing'!$A:$A,I$4,'Raw Data - Packing'!$S:$S) -> 0 | ... GK35: =+SUMIF('Raw Data - Packing'!$A:$A,GK$4,'Raw Data - Packing'!$S:$S) -> 0 | GL35: =SUM(F35:GK35) -> 20283.2 | GM35: =+GL35/SUM($GL$34:$GL$35) -> 0.16915071
A36: Waste % (v Produced) | B36: =IFERROR(SUM(B34:B35)/B25,"") | C36: =IFERROR(SUM(C34:C35)/C25,"") | D36: =IFERROR(SUM(D34:D35)/D25,"") | E36: =IFERROR(SUM(E34:E35)/E25,"") | F36: =IFERROR(SUM(F34:F35)/F25,"") | G36: =IFERROR(SUM(G34:G35)/G25,"") | H36: =IFERROR(SUM(H34:H35)/H25,"") | I36: =IFERROR(SUM(I34:I35)/I25,"") | ... GL36: =IFERROR(SUM(GL34:GL35)/GL25,"") -> 0.10829617
A38: SD To Pack | DL38: =SUMIF('Daily Summary Old'!$A:$A,DL4,'Daily Summary Old'!$L:$L) -> 187118.12 | DM38: =+DL38+DM9-DM10-DM18-DM19 -> 115441.17 | DN38: =+DM38+DN9-DN10-DN18-DN19 -> 115441.17 | DO38: =+DN38+DO9-DO10-DO18-DO19 -> 20848.58
A39: Bao To Pack | DL39: =SUMIF('Daily Summary Old'!$A:$A,DL4,'Daily Summary Old'!$M:$M) -> 42482.5 | DM39: =+DL39-DM25-DM26-DM34-DM35 -> 34922.5 | DN39: =+DM39-DN25-DN26-DN34-DN35 -> 34922.5 | DO39: =+DN39-DO25-DO26-DO34-DO35 -> 34922.5

Sheet Raw Data - Production
D1: # Individual Pieces Formed | K1: Total Waste in #'s | Q1: Pieces SD | R1: Pieces Bao | S1: SD % | T1: Bao % | U1: Downtime Tracker in Minutes | AF1: Daily Goal #
A2: Date | B2: Week # | C2: Month | D2: JBM #1 | E2: JBM #2 | F2: JBM #3 | G2: Rheon #1 | H2: Rheon #2 | I2: Rheon #3 | K2: JBM #1 | L2: JBM #2 | M2: JBM #3 | N2: Rheon #1 | O2: Rheon #2 | P2: Rheon #3 | U2: JBM #1 | V2: JBM #2 | W2: JBM #3 | X2: Rheon #1 | Y2: Rheon #2 | Z2: Rheon #3 | AA2: PFM #1 | AB2: PFM #2 | AC2: Adco #1 | AD2: Adco #2 | AF2: JBM | AG2: Rheon
A3: 46104 | B3: =+WEEKNUM(A3) -> 13 | C3: =+TEXT(A3,"mmmm") -> March | D3: =170*30 -> 5100 | E3: =+D3 -> 5100 | Q3: =+SUM(K3:M3)/Weights!$B$2 -> 0 | R3: =+SUM(N3:O3)/Weights!$B$4 -> 0 | S3: =IFERROR(Q3/SUM(D3:F3),"") -> 0
A4: 46105 | B4: =+WEEKNUM(A4) -> 13 | C4: =+TEXT(A4,"mmmm") -> March | D4: =389*30 -> 11670 | E4: =+D4 -> 11670 | Q4: =+SUM(K4:M4)/Weights!$B$2 -> 0 | R4: =+SUM(N4:O4)/Weights!$B$4 -> 0 | S4: =IFERROR(Q4/SUM(D4:F4),"") -> 0
A5: 46106 | B5: =+WEEKNUM(A5) -> 13 | C5: =+TEXT(A5,"mmmm") -> March | D5: =157*30 -> 4710 | E5: =+D5 -> 4710 | Q5: =+SUM(K5:M5)/Weights!$B$2 -> 0 | R5: =+SUM(N5:O5)/Weights!$B$4 -> 0 | S5: =IFERROR(Q5/SUM(D5:F5),"") -> 0
A6: 46107 | B6: =+WEEKNUM(A6) -> 13 | C6: =+TEXT(A6,"mmmm") -> March | D6: =556*30 -> 16680 | E6: =+D6 -> 16680 | Q6: =+SUM(K6:M6)/Weights!$B$2 -> 0 | R6: =+SUM(N6:O6)/Weights!$B$4 -> 0 | S6: =IFERROR(Q6/SUM(D6:F6),"") -> 0
A7: 46111 | B7: =+WEEKNUM(A7) -> 14 | C7: =+TEXT(A7,"mmmm") -> March | D7: =581*30 -> 17430 | E7: =+D7 -> 17430 | Q7: =+SUM(K7:M7)/Weights!$B$2 -> 0 | R7: =+SUM(N7:P7)/Weights!$B$4 -> 0 | S7: =IFERROR(Q7/SUM(D7:F7),"") -> 0 | AF7: =226800/4 -> 56700 | AG7: 0
A8: 46112 | B8: =+WEEKNUM(A8) -> 14 | C8: =+TEXT(A8,"mmmm") -> March | D8: =558*30 -> 16740 | E8: =+D8 -> 16740 | Q8: =+SUM(K8:M8)/Weights!$B$2 -> 0 | R8: =+SUM(N8:P8)/Weights!$B$4 -> 0 | S8: =IFERROR(Q8/SUM(D8:F8),"") -> 0 | AF8: =226800/4 -> 56700 | AG8: 0
A9: 46113 | B9: =+WEEKNUM(A9) -> 14 | C9: =+TEXT(A9,"mmmm") -> April | D9: =877*30 -> 26310 | E9: =+D9 -> 26310 | Q9: =+SUM(K9:M9)/Weights!$B$2 -> 0 | R9: =+SUM(N9:P9)/Weights!$B$4 -> 0 | S9: =IFERROR(Q9/SUM(D9:F9),"") -> 0 | AF9: =226800/4 -> 56700 | AG9: 0
A10: 46114 | B10: =+WEEKNUM(A10) -> 14 | C10: =+TEXT(A10,"mmmm") -> April | D10: =568*30 -> 17040 | E10: =+D10 -> 17040 | Q10: =+SUM(K10:M10)/Weights!$B$2 -> 0 | R10: =+SUM(N10:P10)/Weights!$B$4 -> 0 | S10: =IFERROR(Q10/SUM(D10:F10),"") -> 0 | AF10: =226800/4 -> 56700 | AG10: 0
A11: 46118 | B11: =+WEEKNUM(A11) -> 15 | C11: =+TEXT(A11,"mmmm") -> April | D11: =537*30 -> 16110 | E11: =+D11 -> 16110 | Q11: =+SUM(K11:M11)/Weights!$B$2 -> 0 | R11: =+SUM(N11:P11)/Weights!$B$4 -> 0 | S11: =IFERROR(Q11/SUM(D11:F11),"") -> 0 | AF11: =226800/4 -> 56700 | AG11: =181440/4 -> 45360
A12: 46119 | B12: =+WEEKNUM(A12) -> 15 | C12: =+TEXT(A12,"mmmm") -> April | D12: =773*30 -> 23190 | E12: =+D12 -> 23190 | Q12: =+SUM(K12:M12)/Weights!$B$2 -> 0 | R12: =+SUM(N12:P12)/Weights!$B$4 -> 0 | S12: =IFERROR(Q12/SUM(D12:F12),"") -> 0 | T12: =IFERROR(R12/SUM(G12:I12),"") | AF12: =226800/4 -> 56700 | AG12: =181440/4 -> 45360
A13: 46120 | B13: =+WEEKNUM(A13) -> 15 | C13: =+TEXT(A13,"mmmm") -> April | D13: =787*30 -> 23610 | E13: =+D13 -> 23610 | Q13: =+SUM(K13:M13)/Weights!$B$2 -> 0 | R13: =+SUM(N13:P13)/Weights!$B$4 -> 0 | S13: =IFERROR(Q13/SUM(D13:F13),"") -> 0 | T13: =IFERROR(R13/SUM(G13:I13),"") | AF13: =226800/4 -> 56700 | AG13: =181440/4 -> 45360
A14: 46121 | B14: =+WEEKNUM(A14) -> 15 | C14: =+TEXT(A14,"mmmm") -> April | D14: =767*30 -> 23010 | E14: =+D14 -> 23010 | Q14: =+SUM(K14:M14)/Weights!$B$2 -> 0 | R14: =+SUM(N14:P14)/Weights!$B$4 -> 0 | S14: =IFERROR(Q14/SUM(D14:F14),"") -> 0 | T14: =IFERROR(R14/SUM(G14:I14),"") | AF14: =226800/4 -> 56700 | AG14: =181440/4 -> 45360
A15: 46125 | B15: =+WEEKNUM(A15) -> 16 | C15: =+TEXT(A15,"mmmm") -> April | D15: =704*30 -> 21120 | E15: =+D15 -> 21120 | Q15: =+SUM(K15:M15)/Weights!$B$2 -> 0 | R15: =+SUM(N15:P15)/Weights!$B$4 -> 0 | S15: =IFERROR(Q15/SUM(D15:F15),"") -> 0 | T15: =IFERROR(R15/SUM(G15:I15),"") | AF15: =226800/4 -> 56700 | AG15: =181440/4 -> 45360
A16: 46126 | B16: =+WEEKNUM(A16) -> 16 | C16: =+TEXT(A16,"mmmm") -> April | D16: =966*30 -> 28980 | E16: =+D16 -> 28980 | K16: 95 | L16: 95 | Q16: =+SUM(K16:M16)/Weights!$B$2 -> 3002.4691 | R16: =+SUM(N16:P16)/Weights!$B$4 -> 0 | S16: =IFERROR(Q16/SUM(D16:F16),"") -> 0.051802435 | T16: =IFERROR(R16/SUM(G16:I16),"") | AF16: =226800/4 -> 56700 | AG16: =181440/4 -> 45360
A17: 46127 | B17: =+WEEKNUM(A17) -> 16 | C17: =+TEXT(A17,"mmmm") -> April | D17: =916*30 -> 27480 | E17: =+D17 -> 27480 | K17: 758 | L17: 758 | Q17: =+SUM(K17:M17)/Weights!$B$2 -> 23956.543 | R17: =+SUM(N17:P17)/Weights!$B$4 -> 0 | S17: =IFERROR(Q17/SUM(D17:F17),"") -> 0.43589052 | T17: =IFERROR(R17/SUM(G17:I17),"") | AF17: =226800/4 -> 56700 | AG17: =181440/4 -> 45360
A18: 46128 | B18: =+WEEKNUM(A18) -> 16 | C18: =+TEXT(A18,"mmmm") -> April | D18: =580*30 -> 17400 | E18: =+D18 -> 17400 | Q18: =+SUM(K18:M18)/Weights!$B$2 -> 0 | R18: =+SUM(N18:P18)/Weights!$B$4 -> 0 | S18: =IFERROR(Q18/SUM(D18:F18),"") -> 0 | T18: =IFERROR(R18/SUM(G18:I18),"") | AF18: =226800/4 -> 56700 | AG18: =181440/4 -> 45360
A19: 46132 | B19: =+WEEKNUM(A19) -> 17 | C19: =+TEXT(A19,"mmmm") -> April | D19: =938*30 -> 28140 | E19: =+D19 -> 28140 | K19: 169 | L19: =+K19 -> 169 | Q19: =+SUM(K19:M19)/Weights!$B$2 -> 5341.2346 | R19: =+SUM(N19:P19)/Weights!$B$4 -> 0 | S19: =IFERROR(Q19/SUM(D19:F19),"") -> 0.094904665 | T19: =IFERROR(R19/SUM(G19:I19),"") | AF19: =226800/4 -> 56700 | AG19: =181440/4 -> 45360
A20: 46133 | B20: =+WEEKNUM(A20) -> 17 | C20: =+TEXT(A20,"mmmm") -> April | D20: =878*30 -> 26340 | E20: =+D20 -> 26340 | K20: 89.5 | L20: =+K20 -> 89.5 | Q20: =+SUM(K20:M20)/Weights!$B$2 -> 2828.642 | R20: =+SUM(N20:P20)/Weights!$B$4 -> 0 | S20: =IFERROR(Q20/SUM(D20:F20),"") -> 0.053694798 | T20: =IFERROR(R20/SUM(G20:I20),"") | AF20: =226800/4 -> 56700 | AG20: =181440/4 -> 45360
A21: 46134 | B21: =+WEEKNUM(A21) -> 17 | C21: =+TEXT(A21,"mmmm") -> April | D21: =1128*30 -> 33840 | E21: =+D21 -> 33840 | K21: 154 | L21: 154 | Q21: =+SUM(K21:M21)/Weights!$B$2 -> 4867.1605 | R21: =+SUM(N21:P21)/Weights!$B$4 -> 0 | S21: =IFERROR(Q21/SUM(D21:F21),"") -> 0.07191431 | T21: =IFERROR(R21/SUM(G21:I21),"") | AF21: =226800/4 -> 56700 | AG21: =181440/4 -> 45360
A22: 46135 | B22: =+WEEKNUM(A22) -> 17 | C22: =+TEXT(A22,"mmmm") -> April | D22: =1170*30 -> 35100 | E22: =+D22 -> 35100 | Q22: =+SUM(K22:M22)/Weights!$B$2 -> 0 | R22: =+SUM(N22:P22)/Weights!$B$4 -> 0 | S22: =IFERROR(Q22/SUM(D22:F22),"") -> 0 | T22: =IFERROR(R22/SUM(G22:I22),"") | AF22: =226800/4 -> 56700 | AG22: =181440/4 -> 45360
A23: 46139 | B23: =+WEEKNUM(A23) -> 18 | C23: =+TEXT(A23,"mmmm") -> April | D23: =1108*30 -> 33240 | E23: =+D23 -> 33240 | K23: 163 | L23: 163 | Q23: =+SUM(K23:M23)/Weights!$B$2 -> 5151.6049 | R23: =+SUM(N23:P23)/Weights!$B$4 -> 0 | S23: =IFERROR(Q23/SUM(D23:F23),"") -> 0.077491049 | T23: =IFERROR(R23/SUM(G23:I23),"") | AF23: =226800/4 -> 56700 | AG23: =181440/4 -> 45360
A24: 46140 | B24: =+WEEKNUM(A24) -> 18 | C24: =+TEXT(A24,"mmmm") -> April | D24: =1119*30 -> 33570 | E24: =+D24 -> 33570 | Q24: =+SUM(K24:M24)/Weights!$B$2 -> 0 | R24: =+SUM(N24:P24)/Weights!$B$4 -> 0 | S24: =IFERROR(Q24/SUM(D24:F24),"") -> 0 | T24: =IFERROR(R24/SUM(G24:I24),"") | AF24: =226800/4 -> 56700 | AG24: =181440/4 -> 45360
A25: 46141 | B25: =+WEEKNUM(A25) -> 18 | C25: =+TEXT(A25,"mmmm") -> April | D25: =1266*30 -> 37980 | E25: =+D25 -> 37980 | K25: =538.5/2 -> 269.25 | L25: =+K25 -> 269.25 | Q25: =+SUM(K25:M25)/Weights!$B$2 -> 8509.6296 | R25: =+SUM(N25:P25)/Weights!$B$4 -> 0 | S25: =IFERROR(Q25/SUM(D25:F25),"") -> 0.11202777 | T25: =IFERROR(R25/SUM(G25:I25),"") | AF25: =226800/4 -> 56700 | AG25: =181440/4 -> 45360
A26: 46142 | B26: =+WEEKNUM(A26) -> 18 | C26: =+TEXT(A26,"mmmm") -> April | D26: =1504.5*30 -> 45135 | E26: =+D26 -> 45135 | K26: 180 | L26: 180 | Q26: =+SUM(K26:M26)/Weights!$B$2 -> 5688.8889 | R26: =+SUM(N26:P26)/Weights!$B$4 -> 0 | S26: =IFERROR(Q26/SUM(D26:F26),"") -> 0.063020814 | T26: =IFERROR(R26/SUM(G26:I26),"") | AF26: =226800/4 -> 56700 | AG26: =181440/4 -> 45360
